Workbook

Sheet Project_Info
A1: TIO2 SPRINT INTELLIGENCE · PROJECT INFORMATION
A2: Project Name | B2: Sponsor | C2: Business Unit | D2: Project Manager | E2: Start Date | F2: Target End Date | G2: Sprint Length (Days) | H2: Methodology | I2: Customer | J2: Status
A3: TIO2 – Telematics Gateway ECU Modernization | B3: Dr. Klaus Bergmann | C3: Commercial Vehicles | D3: Suresh Iyer | E3: 2026-04-21 | F3: 2026-08-10 | G3: 14 | H3: Agile Scrum | I3: Daimler Truck | J3: Active
A5: KEY PROJECT METRICS
A6: Total Sprints | B6: 8
A7: Sprint Length (days) | B7: 14
A8: Target Confidence Level | B8: 80%
A9: Current Sprint | B9: 6
A10: Sprints Completed | B10: 5
A11: Sprints Remaining | B11: 2
A12: Total Team Size | B12: 9
A13: Technology Domain | B13: Automotive Embedded Software
A14: Compliance Target | B14: MISRA C:2012, ASPICE L2
A15: Release Cadence | B15: 45-Day Delivery Cycle

Sheet Team
A1: TIO2 – TEAM RESOURCE REGISTER
A2: Resource Name | B2: Role | C2: Skill 1 | D2: Skill 1 Level | E2: Skill 2 | F2: Skill 2 Level | G2: Skill 3 | H2: Skill 3 Level | I2: S1 Alloc % | J2: S1 Avail % | K2: S2 Alloc % | L2: S2 Avail % | M2: S3 Alloc % | N2: S3 Avail % | O2: S4 Alloc % | P2: S4 Avail % | Q2: S5 Alloc % | R2: S5 Avail % | S2: S6 Alloc % | T2: S6 Avail % | U2: S7 Alloc % | V2: S7 Avail % | W2: S8 Alloc % | X2: S8 Avail %
A3: Karthik Subramaniam | B3: Technical Lead / AUTOSAR Architect | C3: AUTOSAR Stack Configuration | D3: L1-Expert | E3: MCAL Driver Integration | F3: L2-Advanced | G3: OS Task Scheduling | H3: L2-Advanced | I3: 1 | J3: 1 | K3: 1 | L3: 1 | M3: 1 | N3: 1 | O3: 1 | P3: 1 | Q3: 1 | R3: 1 | S3: 1 | U3: 1 | W3: 1
A4: Priya Meenakshi | B4: Senior CAN / Protocols Engineer | C4: CAN / J1939 Protocol Development | D4: L1-Expert | E4: COM Stack & Signal Mapping | F4: L2-Advanced | G4: CANoe Scripting | H4: L3-Intermediate | I4: 0.8 | J4: 1 | K4: 0.8 | L4: 1 | M4: 0.8 | N4: 1 | O4: 0.8 | P4: 1 | Q4: 0.8 | R4: 1 | S4: 0.8 | U4: 0.8 | W4: 0.8
A5: Arjun Sundaram | B5: Diagnostics Engineer | C5: UDS Diagnostics & DTC Management | D5: L1-Expert | E5: DCM / DEM Module Configuration | F5: L2-Advanced | G5: ASPICE Audit Support | H5: L3-Intermediate | I5: 1 | J5: 1 | K5: 1 | L5: 1 | M5: 1 | N5: 0.8 | O5: 1 | P5: 0.8 | Q5: 1 | R5: 1 | S5: 1 | U5: 1 | W5: 1
A6: Vikram Narayanan | B6: System Architect / Integration Lead | C6: ECU Integration & Gateway Routing | D6: L1-Expert | E6: PDU Configuration | F6: L2-Advanced | G6: Fleet Telemetry | H6: L2-Advanced | I6: 1 | J6: 1 | K6: 1 | L6: 1 | M6: 1 | N6: 1 | O6: 1 | P6: 1 | Q6: 1 | R6: 1 | S6: 1 | U6: 1 | W6: 1
A7: Akshaya Krishnan | B7: Test Engineer | C7: HIL Testing & CANoe Automation | D7: L2-Advanced | E7: Regression & Integration Testing | F7: L2-Advanced | G7: OTA Validation | H7: L3-Intermediate | I7: 0.7 | J7: 1 | K7: 0.7 | L7: 1 | M7: 0.5 | N7: 1 | O7: 0.7 | P7: 1 | Q7: 0.7 | R7: 0.7 | S7: 0.7 | U7: 0.7 | W7: 0.7
A8: Sandeep Annamalai | B8: Cybersecurity Engineer | C8: Automotive Cybersecurity (EVITA) | D8: L2-Advanced | E8: SecOC & Secure Boot | F8: L2-Advanced | G8: HSM Integration | H8: L3-Intermediate | I8: 0.8 | J8: 0.8 | K8: 0.8 | L8: 0.8 | M8: 0.8 | N8: 0.8 | O8: 0.8 | P8: 0.8 | Q8: 0.8 | R8: 0.4 | S8: 0.8 | U8: 0.8 | W8: 0.8
A9: Divya Rajalakshmi | B9: Scrum Master | C9: Agile Delivery & Sprint Tracking | D9: L1-Expert | E9: Stakeholder Communication | F9: L2-Advanced | G9: DoD Governance | H9: L2-Advanced | I9: 1 | J9: 1 | K9: 1 | L9: 1 | M9: 1 | N9: 1 | O9: 1 | P9: 1 | Q9: 1 | R9: 1 | S9: 1 | U9: 1 | W9: 1
A10: Meena Balasubramanian | B10: OTA / Firmware Engineer | C10: OTA Firmware Update Mechanisms | D10: L2-Advanced | E10: Manifest & Delta Packaging | F10: L3-Intermediate | G10: Backend API Integration | H10: L4-Beginner | I10: 1 | J10: 1 | K10: 1 | L10: 1 | M10: 1 | N10: 1 | O10: 1 | P10: 1 | Q10: 1 | R10: 1 | S10: 1 | U10: 1 | W10: 1
A11: Ravi Chandran | B11: Junior Test / Integration Engineer | C11: Regression & Integration Testing | D11: L3-Intermediate | E11: HIL Testing & CANoe Automation | F11: L4-Beginner | G11: OTA Validation | H11: L4-Beginner | I11: 0 | J11: 0 | K11: 0 | L11: 0 | M11: 1 | N11: 1 | O11: 1 | P11: 1 | Q11: 1 | R11: 1 | S11: 1 | U11: 1 | W11: 1
A13: Skill Levels: L1=Expert | L2=Advanced | L3=Intermediate | L4=Beginner

Sheet Sprint_Plan
A1: TIO2 – SPRINT PLAN
A2: Sprint Name | B2: Start Date | C2: End Date | D2: Duration (Days) | E2: Sprint Goal | F2: Status | G2: Velocity (h) | H2: Carry-Over Items
A3: Sprint 1 | B3: 2026-04-21 | C3: 2026-05-04 | D3: 14 | E3: Platform Setup — dev environment, ETAS ISOLAR-A/B toolchain, AUTOSAR BSW baseline (MICROSAR), CAN driver scaffolding, ECU HAL init, OS task scheduling, CI pipeline. | F3: Completed | G3: =SUMIF(Work_Items!$D$3:$D$72,$A3,Work_Items!$K$3:$K$72) -> 253 | H3: =COUNTIF(Work_Items!$E$3:$E$72,$A3)-COUNTIFS(Work_Items!$E$3:$E$72,$A3,Work_Items!$D$3:$D$72,$A3,Work_Items!$N$3:$N$72,"Completed") -> 1
A4: Sprint 2 | B4: 2026-05-05 | C4: 2026-05-18 | D4: 14 | E4: CAN Communication — J1939 stack, CAN frame routing, signal mapping, PDU configuration, gateway routing table, CANoe test harness, address claiming. | F4: Completed | G4: =SUMIF(Work_Items!$D$3:$D$72,$A4,Work_Items!$K$3:$K$72) -> 229 | H4: =COUNTIF(Work_Items!$E$3:$E$72,$A4)-COUNTIFS(Work_Items!$E$3:$E$72,$A4,Work_Items!$D$3:$D$72,$A4,Work_Items!$N$3:$N$72,"Completed") -> 1
A5: Sprint 3 | B5: 2026-05-19 | C5: 2026-06-01 | D5: 14 | E5: Diagnostics — UDS services (0x10/0x19/0x22/0x27/0x2E), DTC management, session control. New joiner (Ravi) onboarded. BLK-001 OEM spec blocker caused partial rework on UDS. | F5: Completed | G5: =SUMIF(Work_Items!$D$3:$D$72,$A5,Work_Items!$K$3:$K$72) -> 271 | H5: =COUNTIF(Work_Items!$E$3:$E$72,$A5)-COUNTIFS(Work_Items!$E$3:$E$72,$A5,Work_Items!$D$3:$D$72,$A5,Work_Items!$N$3:$N$72,"Completed") -> 1
A6: Sprint 4 | B6: 2026-06-02 | C6: 2026-06-15 | D6: 14 | E6: AUTOSAR Integration — RTE generation, SWC mapping, MCAL (SPI/LIN/Eth), DCM/DEM, COM signal routing, NvM. COM stack rework loop. BLK-003 HW bench blocked 3 WIs (rescheduled to S5). | F6: Completed | G6: =SUMIF(Work_Items!$D$3:$D$72,$A6,Work_Items!$K$3:$K$72) -> 256 | H6: =COUNTIF(Work_Items!$E$3:$E$72,$A6)-COUNTIFS(Work_Items!$E$3:$E$72,$A6,Work_Items!$D$3:$D$72,$A6,Work_Items!$N$3:$N$72,"Completed") -> 3
A7: Sprint 5 | B7: 2026-06-16 | C7: 2026-06-29 | D7: 14 | E7: Cybersecurity — SecOC, HSM key mgmt, secure boot, TLS 1.3, EVITA HSM driver, IDS. Sandeep sick leave (8 days). 2 WIs carried to S6. BLK-004 (Daimler API) open. | F7: Completed | G7: =SUMIF(Work_Items!$D$3:$D$72,$A7,Work_Items!$K$3:$K$72) -> 347 | H7: =COUNTIF(Work_Items!$E$3:$E$72,$A7)-COUNTIFS(Work_Items!$E$3:$E$72,$A7,Work_Items!$D$3:$D$72,$A7,Work_Items!$N$3:$N$72,"Completed") -> 2
A8: Sprint 6 | B8: 2026-06-30 | C8: 2026-07-13 | D8: 14 | E8: OTA Updates — delta packaging, session manager, rollback, manifest validation. BLK-004 resolution critical. TLS 1.3 + IDS carry-overs from S5. | F8: In Progress | G8: =SUMIF(Work_Items!$D$3:$D$72,$A8,Work_Items!$K$3:$K$72) -> 0 | H8: 0
A9: Sprint 7 | B9: 2026-07-14 | C9: 2026-07-27 | D9: 14 | E9: System Integration — E2E HIL bench, gateway routing validation, CAN+UDS+OTA regression, telemetry signal validation on target HW. | F9: Not Started | G9: =SUMIF(Work_Items!$D$3:$D$72,$A9,Work_Items!$K$3:$K$72) -> 0 | H9: 0
A10: Sprint 8 | B10: 2026-07-28 | C10: 2026-08-10 | D10: 14 | E10: Release Readiness — FOTA E2E, MISRA C:2012 compliance, ASPICE L2 docs, Daimler Truck sign-off. | F10: Not Started | G10: =SUMIF(Work_Items!$D$3:$D$72,$A10,Work_Items!$K$3:$K$72) -> 0 | H10: 0

Sheet Work_Items
A1: TIO2 – WORK ITEM REGISTER (Sprint Backlog & Actuals)
A2: Task ID | B2: Task Name | C2: Type | D2: Sprint | E2: Orig. Sprint | F2: Owner | G2: Required Skill | H2: Priority | I2: Orig Est (h) | J2: Curr Est (h) | K2: Actual Hrs | L2: Remaining Hrs | M2: Progress % | N2: Status | O2: Scope Change | P2: Scope Reason
A3: WI-001 | B3: AUTOSAR BSW Baseline Configuration | C3: Feature | D3: Sprint 1 | E3: Sprint 1 | F3: Karthik Subramaniam | G3: AUTOSAR Stack Configuration | H3: High | I3: 40 | J3: 48 | K3: 50 | L3: 0 | M3: =MIN(IFERROR(K3/J3,0),1) -> 1 | N3: Completed | O3: Yes | P3: Technical Debt
A4: WI-002 | B4: Development Toolchain Setup (ETAS ISOLAR-A/B) | C4: Task | D4: Sprint 1 | E4: Sprint 1 | F4: Vikram Narayanan | G4: ECU Integration & Gateway Routing | H4: High | I4: 16 | J4: 16 | K4: 19 | L4: 0 | M4: =MIN(IFERROR(K4/J4,0),1) -> 1 | N4: Completed | O4: No
A5: WI-003 | B5: CAN Driver Scaffolding | C5: Story | D5: Sprint 1 | E5: Sprint 1 | F5: Priya Meenakshi | G5: CAN / J1939 Protocol Development | H5: High | I5: 24 | J5: 28 | K5: 30 | L5: 0 | M5: =MIN(IFERROR(K5/J5,0),1) -> 1 | N5: Completed | O5: Yes | P5: Technical Debt
A6: WI-004 | B6: ECU Hardware Abstraction Layer (MCAL Init) | C6: Feature | D6: Sprint 1 | E6: Sprint 1 | F6: Karthik Subramaniam | G6: MCAL Driver Integration | H6: High | I6: 32 | J6: 36 | K6: 38 | L6: 0 | M6: =MIN(IFERROR(K6/J6,0),1) -> 1 | N6: Completed | O6: Yes | P6: Customer Request
A7: WI-005 | B7: CANoe Test Environment Setup | C7: Task | D7: Sprint 1 | E7: Sprint 1 | F7: Akshaya Krishnan | G7: HIL Testing & CANoe Automation | H7: Medium | I7: 12 | J7: 12 | K7: 13 | L7: 0 | M7: =MIN(IFERROR(K7/J7,0),1) -> 1 | N7: Completed | O7: No
A8: WI-006 | B8: AUTOSAR OS Task Scheduling Configuration | C8: Story | D8: Sprint 1 | E8: Sprint 1 | F8: Karthik Subramaniam | G8: AUTOSAR Stack Configuration | H8: High | I8: 20 | J8: 24 | K8: 25 | L8: 0 | M8: =MIN(IFERROR(K8/J8,0),1) -> 1 | N8: Completed | O8: Yes | P8: Technical Debt
A9: WI-007 | B9: Spike: Evaluate ETAS RTA-OS vs MICROSAR OS | C9: Spike | D9: Sprint 1 | E9: Sprint 1 | F9: Vikram Narayanan | G9: ECU Integration & Gateway Routing | H9: High | I9: 16 | J9: 16 | K9: 17 | L9: 0 | M9: =MIN(IFERROR(K9/J9,0),1) -> 1 | N9: Completed | O9: No
A10: WI-008 | B10: COM Stack Initial Configuration | C10: Story | D10: Sprint 1 | E10: Sprint 1 | F10: Priya Meenakshi | G10: COM Stack & Signal Mapping | H10: Medium | I10: 16 | J10: 20 | K10: 32 | L10: 0 | M10: =MIN(IFERROR(K10/J10,0),1) -> 1 | N10: Completed | O10: Yes | P10: Enhancement
A11: WI-009 | B11: Version Control & CI Pipeline Setup | C11: Task | D11: Sprint 1 | E11: Sprint 1 | F11: Sandeep Annamalai | G11: Automotive Cybersecurity (EVITA) | H11: Medium | I11: 12 | J11: 12 | K11: 21 | L11: 0 | M11: =MIN(IFERROR(K11/J11,0),1) -> 1 | N11: Completed | O11: No
A12: WI-010 | B12: Sprint 1 Definition of Done Review | C12: Task | D12: Sprint 1 | E12: Sprint 1 | F12: Divya Rajalakshmi | G12: Agile Delivery & Sprint Tracking | H12: Low | I12: 8 | J12: 8 | K12: 8 | L12: 0 | M12: =MIN(IFERROR(K12/J12,0),1) -> 1 | N12: Completed | O12: No
A13: WI-011 | B13: J1939 Protocol Stack Integration | C13: Feature | D13: Sprint 2 | E13: Sprint 2 | F13: Priya Meenakshi | G13: CAN / J1939 Protocol Development | H13: High | I13: 40 | J13: 48 | K13: 50 | L13: 0 | M13: =MIN(IFERROR(K13/J13,0),1) -> 1 | N13: Completed | O13: Yes | P13: Customer Request
A14: WI-012 | B14: CAN Frame Routing Logic Implementation | C14: Feature | D14: Sprint 2 | E14: Sprint 2 | F14: Priya Meenakshi | G14: CAN / J1939 Protocol Development | H14: High | I14: 32 | J14: 36 | K14: 37 | L14: 0 | M14: =MIN(IFERROR(K14/J14,0),1) -> 1 | N14: Completed | O14: Yes | P14: Technical Debt
A15: WI-013 | B15: Signal Mapping & PDU Configuration | C15: Story | D15: Sprint 2 | E15: Sprint 2 | F15: Vikram Narayanan | G15: PDU Configuration | H15: High | I15: 24 | J15: 24 | K15: 25 | L15: 0 | M15: =MIN(IFERROR(K15/J15,0),1) -> 1 | N15: Completed | O15: No
A16: WI-014 | B16: CAN Gateway Routing Table Configuration | C16: Story | D16: Sprint 2 | E16: Sprint 2 | F16: Vikram Narayanan | G16: ECU Integration & Gateway Routing | H16: High | I16: 20 | J16: 26 | K16: 27 | L16: 0 | M16: =MIN(IFERROR(K16/J16,0),1) -> 1 | N16: Completed | O16: Yes | P16: Customer Request
A17: WI-015 | B17: CANoe Automated Test Harness (CAN Layer) | C17: Task | D17: Sprint 2 | E17: Sprint 2 | F17: Akshaya Krishnan | G17: HIL Testing & CANoe Automation | H17: Medium | I17: 20 | J17: 20 | K17: 21 | L17: 0 | M17: =MIN(IFERROR(K17/J17,0),1) -> 1 | N17: Completed | O17: No
A18: WI-016 | B18: Spike: CAN FD Feasibility for High-BW Signals | C18: Spike | D18: Sprint 2 | E18: Sprint 2 | F18: Vikram Narayanan | G18: ECU Integration & Gateway Routing | H18: Medium | I18: 12 | J18: 12 | K18: 12 | L18: 0 | M18: =MIN(IFERROR(K18/J18,0),1) -> 1 | N18: Completed | O18: No
A19: WI-017 | B19: CAN Bus Error Handling & Fault Injection Tests | C19: Story | D19: Sprint 2 | E19: Sprint 2 | F19: Akshaya Krishnan | G19: HIL Testing & CANoe Automation | H19: Medium | I19: 16 | J19: 20 | K19: 20 | L19: 0 | M19: =MIN(IFERROR(K19/J19,0),1) -> 1 | N19: Completed | O19: No
A20: WI-018 | B20: J1939 Address Claiming Procedure | C20: Story | D20: Sprint 2 | E20: Sprint 2 | F20: Priya Meenakshi | G20: CAN / J1939 Protocol Development | H20: High | I20: 16 | J20: 16 | K20: 17 | L20: 0 | M20: =MIN(IFERROR(K20/J20,0),1) -> 1 | N20: Completed | O20: Yes | P20: Regulatory
A21: WI-019 | B21: [CO-S1] Fleet Telemetry Preliminary Design | C21: Story | D21: Sprint 2 | E21: Sprint 1 | F21: Vikram Narayanan | G21: ECU Integration & Gateway Routing | H21: Medium | I21: 16 | J21: 20 | K21: 20 | L21: 0 | M21: =MIN(IFERROR(K21/J21,0),1) -> 1 | N21: Completed | O21: No
A22: WI-020 | B22: UDS Service 0x10 – Diagnostic Session Control | C22: Feature | D22: Sprint 3 | E22: Sprint 3 | F22: Arjun Sundaram | G22: UDS Diagnostics & DTC Management | H22: High | I22: 24 | J22: 28 | K22: 31 | L22: 0 | M22: =MIN(IFERROR(K22/J22,0),1) -> 1 | N22: Completed | O22: No
A23: WI-021 | B23: UDS Service 0x27 – Security Access | C23: Feature | D23: Sprint 3 | E23: Sprint 3 | F23: Arjun Sundaram | G23: UDS Diagnostics & DTC Management | H23: High | I23: 20 | J23: 24 | K23: 27 | L23: 0 | M23: =MIN(IFERROR(K23/J23,0),1) -> 1 | N23: Completed | O23: Yes | P23: Technical Debt
A24: WI-022 | B24: UDS Service 0x19 – Read DTC Information | C24: Feature | D24: Sprint 3 | E24: Sprint 3 | F24: Arjun Sundaram | G24: UDS Diagnostics & DTC Management | H24: High | I24: 24 | J24: 30 | K24: 38 | L24: 0 | M24: =MIN(IFERROR(K24/J24,0),1) -> 1 | N24: Completed | O24: Yes | P24: Customer Request
A25: WI-023 | B25: DTC Management – Fault Storage & Ageing | C25: Story | D25: Sprint 3 | E25: Sprint 3 | F25: Arjun Sundaram | G25: UDS Diagnostics & DTC Management | H25: High | I25: 20 | J25: 24 | K25: 26 | L25: 0 | M25: =MIN(IFERROR(K25/J25,0),1) -> 1 | N25: Completed | O25: No
A26: WI-024 | B26: UDS Service 0x22/0x2E – Data Identifier R/W | C26: Story | D26: Sprint 3 | E26: Sprint 3 | F26: Arjun Sundaram | G26: UDS Diagnostics & DTC Management | H26: High | I26: 16 | J26: 20 | K26: 22 | L26: 0 | M26: =MIN(IFERROR(K26/J26,0),1) -> 1 | N26: Completed | O26: Yes | P26: Enhancement
A27: WI-025 | B27: Diagnostic Logging Module | C27: Story | D27: Sprint 3 | E27: Sprint 3 | F27: Karthik Subramaniam | G27: AUTOSAR Stack Configuration | H27: Medium | I27: 16 | J27: 16 | K27: 17 | L27: 0 | M27: =MIN(IFERROR(K27/J27,0),1) -> 1 | N27: Completed | O27: No
A28: WI-026 | B28: CANoe Diagnostic Test Script (KWP/UDS) | C28: Task | D28: Sprint 3 | E28: Sprint 3 | F28: Akshaya Krishnan | G28: CANoe Scripting | H28: Medium | I28: 16 | J28: 20 | K28: 38 | L28: 0 | M28: =MIN(IFERROR(K28/J28,0),1) -> 1 | N28: Completed | O28: No
A29: WI-027 | B29: Defect: UDS 0x10 Session Timeout Not Honoured | C29: Defect | D29: Sprint 3 | E29: Sprint 3 | F29: Arjun Sundaram | G29: UDS Diagnostics & DTC Management | H29: High | I29: 8 | J29: 8 | K29: 10 | L29: 0 | M29: =MIN(IFERROR(K29/J29,0),1) -> 1 | N29: Completed | O29: No
A30: WI-028 | B30: [CO-S2] COM Stack PDU Routing Hardening | C30: Story | D30: Sprint 3 | E30: Sprint 2 | F30: Priya Meenakshi | G30: COM Stack & Signal Mapping | H30: Medium | I30: 16 | J30: 20 | K30: 22 | L30: 0 | M30: =MIN(IFERROR(K30/J30,0),1) -> 1 | N30: Completed | O30: No
A31: WI-029 | B31: Knowledge Transfer: Ravi Chandran Onboarding | C31: Task | D31: Sprint 3 | E31: Sprint 3 | F31: Akshaya Krishnan | G31: HIL Testing & CANoe Automation | H31: Medium | I31: 0 | J31: 40 | K31: 40 | L31: 0 | M31: =MIN(IFERROR(K31/J31,0),1) -> 1 | N31: Completed | O31: Yes | P31: Other
A32: WI-030 | B32: AUTOSAR RTE Generation & SWC Port Mapping | C32: Feature | D32: Sprint 4 | E32: Sprint 4 | F32: Karthik Subramaniam | G32: AUTOSAR Stack Configuration | H32: High | I32: 40 | J32: 52 | K32: 54 | L32: 0 | M32: =MIN(IFERROR(K32/J32,0),1) -> 1 | N32: Completed | O32: Yes | P32: Customer Request
A33: WI-031 | B33: MCAL Driver Integration (SPI, LIN, Ethernet) | C33: Feature | D33: Sprint 4 | E33: Sprint 4 | F33: Karthik Subramaniam | G33: MCAL Driver Integration | H33: High | I33: 32 | J33: 38 | K33: 40 | L33: 0 | M33: =MIN(IFERROR(K33/J33,0),1) -> 1 | N33: Completed | O33: No
A34: WI-032 | B34: Diagnostic Session Manager Refactor | C34: Story | D34: Sprint 4 | E34: Sprint 3 | F34: Arjun Sundaram | G34: DCM / DEM Module Configuration | H34: High | I34: 16 | J34: 22 | K34: 26 | L34: 0 | M34: =MIN(IFERROR(K34/J34,0),1) -> 1 | N34: Completed | O34: No
A35: WI-033 | B35: COM Stack Signal Routing Rework | C35: Defect | D35: Sprint 4 | E35: Sprint 4 | F35: Priya Meenakshi | G35: COM Stack & Signal Mapping | H35: High | I35: 0 | J35: 18 | K35: 18 | L35: 0 | M35: =MIN(IFERROR(K35/J35,0),1) -> 1 | N35: Completed | O35: Yes | P35: Defect
A36: WI-034 | B36: DCM Module Configuration & Session Handling | C36: Story | D36: Sprint 4 | E36: Sprint 4 | F36: Meena Balasubramanian | G36: DCM / DEM Module Configuration | H36: High | I36: 20 | J36: 24 | K36: 36 | L36: 0 | M36: =MIN(IFERROR(K36/J36,0),1) -> 1 | N36: Completed | O36: No
A37: WI-035 | B37: DEM Module Configuration & Event Handling | C37: Story | D37: Sprint 4 | E37: Sprint 4 | F37: Arjun Sundaram | G37: DCM / DEM Module Configuration | H37: High | I37: 20 | J37: 24 | K37: 25 | L37: 0 | M37: =MIN(IFERROR(K37/J37,0),1) -> 1 | N37: Completed | O37: No
A38: WI-036 | B38: NvM Module – Non-Volatile Storage Configuration | C38: Story | D38: Sprint 4 | E38: Sprint 4 | F38: Karthik Subramaniam | G38: AUTOSAR Stack Configuration | H38: Medium | I38: 16 | J38: 20 | K38: 21 | L38: 0 | M38: =MIN(IFERROR(K38/J38,0),1) -> 1 | N38: Completed | O38: No
A39: WI-037 | B39: AUTOSAR Integration Test – RTE Scheduler (Shadow) | C39: Task | D39: Sprint 4 | E39: Sprint 4 | F39: Ravi Chandran | G39: HIL Testing & CANoe Automation | H39: Medium | I39: 16 | J39: 16 | K39: 28 | L39: 0 | M39: =MIN(IFERROR(K39/J39,0),1) -> 1 | N39: Completed | O39: No
A40: WI-038 | B40: Sprint 4 DoD Review | C40: Task | D40: Sprint 4 | E40: Sprint 4 | F40: Divya Rajalakshmi | G40: Agile Delivery & Sprint Tracking | H40: Low | I40: 8 | J40: 8 | K40: 8 | L40: 0 | M40: =MIN(IFERROR(K40/J40,0),1) -> 1 | N40: Completed | O40: No
...

Sheet Dependencies
A1: TIO2 – DEPENDENCY REGISTER (Critical Path & Lag Analysis)
A2: Dep ID | B2: Predecessor Task | C2: Successor Task | D2: Dependency Type | E2: Lag Days
A3: DEP-001 | B3: WI-001 | C3: WI-003 | D3: Finish-To-Start | E3: 0
A4: DEP-002 | B4: WI-001 | C4: WI-004 | D4: Finish-To-Start | E4: 0
A5: DEP-003 | B5: WI-003 | C5: WI-011 | D5: Finish-To-Start | E5: 0
A6: DEP-004 | B6: WI-003 | C6: WI-013 | D6: Finish-To-Start | E6: 0
A7: DEP-005 | B7: WI-011 | C7: WI-020 | D7: Finish-To-Start | E7: 0
A8: DEP-006 | B8: WI-023 | C8: WI-025 | D8: Finish-To-Start | E8: 0
A9: DEP-007 | B9: WI-004 | C9: WI-030 | D9: Finish-To-Start | E9: 0
A10: DEP-008 | B10: WI-020 | C10: WI-034 | D10: Finish-To-Start | E10: 0
A11: DEP-009 | B11: WI-030 | C11: WI-044 | D11: Finish-To-Start | E11: 1
A12: DEP-010 | B12: WI-045 | C12: WI-046 | D12: Finish-To-Start | E12: 2
A13: DEP-011 | B13: WI-046 | C13: WI-053 | D13: Finish-To-Start | E13: 2
A14: DEP-012 | B14: WI-053 | C14: WI-057 | D14: Finish-To-Start | E14: 1
... A25: DEP-023 | B25: WI-032 | C25: WI-035 | D25: Finish-To-Start | E25: 0

Sheet Blockers
A1: TIO2 – BLOCKER REGISTER
A2: Blocker ID | B2: Related Task | C2: Impacted Task IDs | D2: Severity | E2: Status | F2: Owner | G2: Raised Date | H2: Target Resolution | I2: Actual Resolution | J2: Category | K2: Sprint Identified | L2: Notes
A3: BLK-001 | B3: WI-022 | C3: WI-022, WI-027, WI-040 | D3: Critical | E3: Resolved | F3: Arjun Sundaram | G3: 2026-05-19 | H3: 2026-05-28 | I3: 2026-05-29 | J3: External Team Dependency | K3: Sprint 3 | L3: OEM spec for UDS 0x19 arrived late; forced partial rework on DTC read services. Resolved after OEM clarification.
A4: BLK-002 | B4: WI-015 | C4: WI-015, WI-017, WI-026 | D4: High | E4: Resolved | F4: Akshaya Krishnan | G4: 2026-05-05 | H4: 2026-05-14 | I4: 2026-05-13 | J4: Tool Issue | K4: Sprint 2 | L4: CANoe license server outage blocked CAN automated tests. Vendor issued temp license to unblock.
A5: BLK-003 | B5: WI-039 | C5: WI-039, WI-040, WI-041 | D5: High | E5: Resolved | F5: Vikram Narayanan | G5: 2026-06-01 | H5: 2026-06-10 | I5: 2026-06-10 | J5: Lab Issue | K5: Sprint 3 | L5: HIL bench hardware unavailable due to lab procurement delay. WI-039/040/041 rescheduled to S5.
A6: BLK-004 | B6: WI-056 | C6: WI-056, WI-058, WI-041 | D6: High | E6: Open | F6: Meena Balasubramanian | G6: 2026-06-16 | H6: 2026-06-25 | I6: Open | J6: External Team Dependency | K6: Sprint 5 | L6: Daimler API credentials for backend OTA integration not provisioned. Blocking WI-056/058. Open.
A7: BLK-005 | B7: WI-048 | C7: WI-048, WI-052 | D7: Medium | E7: Resolved | F7: Ravi Chandran | G7: 2026-06-16 | H7: 2026-06-22 | I7: 2026-06-21 | J7: Tool Issue | K7: Sprint 5 | L7: Cybersecurity toolchain (HSM simulator) misconfigured; blocked WI-048 attack surface tests. Fixed by tool team.

Sheet Lists
A1: TIO2 – REFERENCE LISTS (Data Validation Sources)
A2: ProjectStatus | B2: SprintStatus | C2: WorkItemType | D2: Priority | E2: WorkItemStatus | F2: YesNo | G2: ScopeReason | H2: DependencyType | I2: Severity | J2: BlockerStatus | K2: BlockerCategory | L2: Owners | M2: Skills | N2: Sprints | O2: SkillCategory
A3: Active | B3: Not Started | C3: Feature | D3: Critical | E3: Not Started | F3: Yes | G3: Customer Request | H3: Finish-To-Start | I3: Low | J3: Open | K3: Lab Issue | L3: Karthik Subramaniam | M3: AUTOSAR Stack Configuration | N3: Sprint 1 | O3: Architecture
A4: On Hold | B4: In Progress | C4: Story | D4: High | E4: In Progress | F4: No | G4: Technical Debt | H4: Start-To-Start | I4: Medium | J4: In Progress | K4: Hardware / Procurement | L4: Priya Meenakshi | M4: MCAL Driver Integration | N4: Sprint 2 | O4: Development
A5: Completed | B5: Completed | C5: Task | D5: Medium | E5: Completed | G5: Regulatory | H5: Finish-To-Finish | I5: High | J5: Resolved | K5: External Team Dependency | L5: Arjun Sundaram | M5: OS Task Scheduling | N5: Sprint 3 | O5: Integration
A6: Cancelled | C6: Defect | D6: Low | E6: Blocked | G6: Defect | I6: Critical | J6: Closed | K6: Tool Issue | L6: Vikram Narayanan | M6: CAN / J1939 Protocol Development | N6: Sprint 4 | O6: Testing
C7: Spike | E7: Deferred | G7: Enhancement | K7: People | L7: Akshaya Krishnan | M7: COM Stack & Signal Mapping | N7: Sprint 5 | O7: Security
G8: Other | L8: Sandeep Annamalai | M8: CANoe Scripting | N8: Sprint 6 | O8: Delivery
L9: Divya Rajalakshmi | M9: UDS Diagnostics & DTC Management | N9: Sprint 7
L10: Meena Balasubramanian | M10: DCM / DEM Module Configuration | N10: Sprint 8
L11: Ravi Chandran | M11: ASPICE Audit Support
M12: ECU Integration & Gateway Routing
M13: PDU Configuration
M14: Fleet Telemetry
M15: HIL Testing & CANoe Automation
M16: Regression & Integration Testing
M17: OTA Validation
M18: Automotive Cybersecurity (EVITA)
M19: SecOC & Secure Boot
M20: HSM Integration
M21: Agile Delivery & Sprint Tracking
M22: Stakeholder Communication
M23: DoD Governance
... M26: Backend API Integration
